# Auth Callback Profile Creation Fix

## üêõ Problem
The error `üìù [AUTH] Error creating profile: [object Object]` was occurring during user registration in the auth callback route.

## üîç Root Cause
The auth callback was using **legacy database schema fields** while the database had been migrated to use the **new isolation schema**:

### Legacy Schema (being used):
- `id: data.session.user.id` (setting profiles.id to auth user id)
- `credits_remaining: 50`
- `credits_used: 0`

### New Schema (actual database):
- `auth_user_id: data.session.user.id` (separate field for auth user link)
- `quota_limit: 50`
- `quota_used: 0`
- RLS policies requiring `auth_user_id = auth.uid()`

## ‚úÖ Solution Applied

### 1. Updated Auth Callback (`frontend/app/auth/callback/route.ts`)
**Before:**
```typescript
.insert({
  id: data.session.user.id,
  email: data.session.user.email,
  full_name: data.session.user.user_metadata?.full_name || null,
  tier: 'free',
  trial_active: true,
  trial_started_at: new Date().toISOString(),
  trial_expires_at: new Date(Date.now() + 7 * 24 * 60 * 60 * 1000).toISOString(),
  credits_remaining: 50,
  credits_used: 0
})
```

**After:**
```typescript
const profileData = {
  auth_user_id: data.session.user.id, // Use auth_user_id instead of id
  email: data.session.user.email,
  full_name: data.session.user.user_metadata?.full_name || null,
  tier: 'free',
  trial_active: true,
  trial_started_at: new Date().toISOString(),
  trial_expires_at: new Date(Date.now() + 7 * 24 * 60 * 60 * 1000).toISOString(),
  quota_limit: 50, // Use quota_limit instead of credits_remaining
  quota_used: 0,   // Use quota_used instead of credits_used
  last_activity_at: new Date().toISOString(),
  user_metadata: {}
}
```

### 2. Updated Profile Lookup
**Before:**
```typescript
.select('id')
.eq('id', data.session.user.id)
```

**After:**
```typescript
.select('id, auth_user_id')
.eq('auth_user_id', data.session.user.id)
```

### 3. Improved Error Logging
Enhanced error logging to show detailed error information instead of `[object Object]`:

```typescript
console.error('‚ùå [AUTH CALLBACK] Error creating profile:', {
  message: insertError.message,
  details: insertError.details,
  hint: insertError.hint,
  code: insertError.code,
  fullError: JSON.stringify(insertError, null, 2)
})
```

### 4. Updated Test API
Also fixed the test-supabase API to use the new schema for consistency.

## üîß Database Schema Changes
The system now uses the enhanced isolation schema:

```sql
-- Key columns in profiles table:
- auth_user_id UUID (links to auth.users.id)
- quota_limit INTEGER (replaces credits_remaining)
- quota_used INTEGER (replaces credits_used)
- last_activity_at TIMESTAMPTZ
- user_metadata JSONB

-- RLS Policy:
CREATE POLICY profiles_user_isolation ON profiles
    FOR ALL USING (auth_user_id = auth.uid());
```

## üß™ Testing
To test the fix:
1. Try signing up with a new email
2. Check the logs for successful profile creation
3. No more `[object Object]` errors should appear

## üìÅ Files Modified
- `frontend/app/auth/callback/route.ts` - Main auth callback fix
- `frontend/app/api/test-supabase/route.ts` - Test API consistency fix

The authentication system should now work correctly with the new database schema and provide proper error messages if any issues occur.
